Workbook
Name Customers: Lookup_Tables!$I$5:$I$34
Name DiscountRates: "tblDiscountRates[Discount%]"
Name NativeTimeline_Date: #N/A
Name PaymentMethods: Lookup_Tables!$C$24:$C$27
Name Products: Lookup_Tables!$F$5:$F$23
Name Salespersons: Lookup_Tables!$B$5:$B$16
Name Slicer_Customer_Type: #N/A
Name Slicer_Product_Category: #N/A
Name Slicer_Region: #N/A
Name Slicer_Saleperson: #N/A

Sheet Raw_Data
A1: Order ID | B1: Date | C1: Month | D1: Saleperson | E1: Region | F1: Customer | G1: Customer Type | H1: Product Category | I1: Product | J1: Quantity | K1: Unit Price | L1: Discount% | M1: Payment Method | N1: Quarter | O1: Year | P1: Gross Sales | Q1: Discount Amount | R1: Net Sales
A2: ="ORD-2026-"&TEXT(ROW()-1,"0000") -> ORD-2026-0001 | B2: 45660 | C2: =TEXT(tblSales[[#This Row],[Date]],"mmmm") -> January | D2: John | E2: =_xlfn.XLOOKUP(tblSales[[#This Row],[Saleperson]],Lookup_Tables!$B$5:$B$16,Lookup_Tables!$C$5:$C$16) -> North | F2: Alpha Distribution | G2: =_xlfn.XLOOKUP(tblSales[[#This Row],[Customer]],Lookup_Tables!$I$5:$I$34,Lookup_Tables!$J$5:$J$34) -> Corporate | H2: =_xlfn.XLOOKUP(tblSales[[#This Row],[Product]],Lookup_Tables!$F$5:$F$23,Lookup_Tables!$E$5:$E$23,"") -> Electronics | I2: Monitor | J2: 6 | K2: =_xlfn.XLOOKUP(tblSales[[#This Row],[Product]],Lookup_Tables!$F$5:$F$23,Lookup_Tables!$G$5:$G$23,"") -> 6000 | L2: =_xlfn.XLOOKUP(tblSales[[#This Row],[Customer Type]],Lookup_Tables!$B$19:$B$21,Lookup_Tables!$C$19:$C$21,0) -> 0.1 | M2: Cash | N2: ="Q"&ROUNDUP(MONTH(tblSales[[#This Row],[Date]])/3,0) -> Q1 | O2: =YEAR(tblSales[[#This Row],[Date]]) -> 2025 | P2: =tblSales[[#This Row],[Quantity]]*tblSales[[#This Row],[Unit Price]] -> 36000 | Q2: =tblSales[[#This Row],[Gross Sales]]*tblSales[[#This Row],[Discount%]] -> 3600 | R2: =tblSales[[#This Row],[Gross Sales]]-tblSales[[#This Row],[Discount Amount]] -> 32400
A3: ="ORD-2026-"&TEXT(ROW()-1,"0000") -> ORD-2026-0002 | B3: 45662 | C3: =TEXT(tblSales[[#This Row],[Date]],"mmmm") -> January | D3: Jane | E3: =_xlfn.XLOOKUP(tblSales[[#This Row],[Saleperson]],Lookup_Tables!$B$5:$B$16,Lookup_Tables!$C$5:$C$16) -> East | F3: Evergreen Supermarket | G3: =_xlfn.XLOOKUP(tblSales[[#This Row],[Customer]],Lookup_Tables!$I$5:$I$34,Lookup_Tables!$J$5:$J$34) -> Retail | H3: =_xlfn.XLOOKUP(tblSales[[#This Row],[Product]],Lookup_Tables!$F$5:$F$23,Lookup_Tables!$E$5:$E$23,"") -> Furniture | I3: Table | J3: 10 | K3: =_xlfn.XLOOKUP(tblSales[[#This Row],[Product]],Lookup_Tables!$F$5:$F$23,Lookup_Tables!$G$5:$G$23,"") -> 7500 | L3: =_xlfn.XLOOKUP(tblSales[[#This Row],[Customer Type]],Lookup_Tables!$B$19:$B$21,Lookup_Tables!$C$19:$C$21,0) -> 0 | M3: Gcash | N3: ="Q"&ROUNDUP(MONTH(tblSales[[#This Row],[Date]])/3,0) -> Q1 | O3: =YEAR(tblSales[[#This Row],[Date]]) -> 2025 | P3: =tblSales[[#This Row],[Quantity]]*tblSales[[#This Row],[Unit Price]] -> 75000 | Q3: =tblSales[[#This Row],[Gross Sales]]*tblSales[[#This Row],[Discount%]] -> 0 | R3: =tblSales[[#This Row],[Gross Sales]]-tblSales[[#This Row],[Discount Amount]] -> 75000
A4: ="ORD-2026-"&TEXT(ROW()-1,"0000") -> ORD-2026-0003 | B4: 45665 | C4: =TEXT(tblSales[[#This Row],[Date]],"mmmm") -> January | D4: Sarah | E4: =_xlfn.XLOOKUP(tblSales[[#This Row],[Saleperson]],Lookup_Tables!$B$5:$B$16,Lookup_Tables!$C$5:$C$16) -> West | F4: City Government | G4: =_xlfn.XLOOKUP(tblSales[[#This Row],[Customer]],Lookup_Tables!$I$5:$I$34,Lookup_Tables!$J$5:$J$34) -> Government | H4: =_xlfn.XLOOKUP(tblSales[[#This Row],[Product]],Lookup_Tables!$F$5:$F$23,Lookup_Tables!$E$5:$E$23,"") -> Office Supplies | I4: Bond Paper | J4: 9 | K4: =_xlfn.XLOOKUP(tblSales[[#This Row],[Product]],Lookup_Tables!$F$5:$F$23,Lookup_Tables!$G$5:$G$23,"") -> 180 | L4: =_xlfn.XLOOKUP(tblSales[[#This Row],[Customer Type]],Lookup_Tables!$B$19:$B$21,Lookup_Tables!$C$19:$C$21,0) -> 0.15 | M4: Cash | N4: ="Q"&ROUNDUP(MONTH(tblSales[[#This Row],[Date]])/3,0) -> Q1 | O4: =YEAR(tblSales[[#This Row],[Date]]) -> 2025 | P4: =tblSales[[#This Row],[Quantity]]*tblSales[[#This Row],[Unit Price]] -> 1620 | Q4: =tblSales[[#This Row],[Gross Sales]]*tblSales[[#This Row],[Discount%]] -> 243 | R4: =tblSales[[#This Row],[Gross Sales]]-tblSales[[#This Row],[Discount Amount]] -> 1377
A5: ="ORD-2026-"&TEXT(ROW()-1,"0000") -> ORD-2026-0004 | B5: 45666 | C5: =TEXT(tblSales[[#This Row],[Date]],"mmmm") -> January | D5: Anna | E5: =_xlfn.XLOOKUP(tblSales[[#This Row],[Saleperson]],Lookup_Tables!$B$5:$B$16,Lookup_Tables!$C$5:$C$16) -> South | F5: Prime Office Supply | G5: =_xlfn.XLOOKUP(tblSales[[#This Row],[Customer]],Lookup_Tables!$I$5:$I$34,Lookup_Tables!$J$5:$J$34) -> Retail | H5: =_xlfn.XLOOKUP(tblSales[[#This Row],[Product]],Lookup_Tables!$F$5:$F$23,Lookup_Tables!$E$5:$E$23,"") -> Electronics | I5: Laptop | J5: 7 | K5: =_xlfn.XLOOKUP(tblSales[[#This Row],[Product]],Lookup_Tables!$F$5:$F$23,Lookup_Tables!$G$5:$G$23,"") -> 20000 | L5: =_xlfn.XLOOKUP(tblSales[[#This Row],[Customer Type]],Lookup_Tables!$B$19:$B$21,Lookup_Tables!$C$19:$C$21,0) -> 0 | M5: Bank Transfer | N5: ="Q"&ROUNDUP(MONTH(tblSales[[#This Row],[Date]])/3,0) -> Q1 | O5: =YEAR(tblSales[[#This Row],[Date]]) -> 2025 | P5: =tblSales[[#This Row],[Quantity]]*tblSales[[#This Row],[Unit Price]] -> 140000 | Q5: =tblSales[[#This Row],[Gross Sales]]*tblSales[[#This Row],[Discount%]] -> 0 | R5: =tblSales[[#This Row],[Gross Sales]]-tblSales[[#This Row],[Discount Amount]] -> 140000
A6: ="ORD-2026-"&TEXT(ROW()-1,"0000") -> ORD-2026-0005 | B6: 45668 | C6: =TEXT(tblSales[[#This Row],[Date]],"mmmm") -> January | D6: Kevin | E6: =_xlfn.XLOOKUP(tblSales[[#This Row],[Saleperson]],Lookup_Tables!$B$5:$B$16,Lookup_Tables!$C$5:$C$16) -> South | F6: Bright Future Academy | G6: =_xlfn.XLOOKUP(tblSales[[#This Row],[Customer]],Lookup_Tables!$I$5:$I$34,Lookup_Tables!$J$5:$J$34) -> Retail | H6: =_xlfn.XLOOKUP(tblSales[[#This Row],[Product]],Lookup_Tables!$F$5:$F$23,Lookup_Tables!$E$5:$E$23,"") -> Electronics | I6: Laptop | J6: 10 | K6: =_xlfn.XLOOKUP(tblSales[[#This Row],[Product]],Lookup_Tables!$F$5:$F$23,Lookup_Tables!$G$5:$G$23,"") -> 20000 | L6: =_xlfn.XLOOKUP(tblSales[[#This Row],[Customer Type]],Lookup_Tables!$B$19:$B$21,Lookup_Tables!$C$19:$C$21,0) -> 0 | M6: Gcash | N6: ="Q"&ROUNDUP(MONTH(tblSales[[#This Row],[Date]])/3,0) -> Q1 | O6: =YEAR(tblSales[[#This Row],[Date]]) -> 2025 | P6: =tblSales[[#This Row],[Quantity]]*tblSales[[#This Row],[Unit Price]] -> 200000 | Q6: =tblSales[[#This Row],[Gross Sales]]*tblSales[[#This Row],[Discount%]] -> 0 | R6: =tblSales[[#This Row],[Gross Sales]]-tblSales[[#This Row],[Discount Amount]] -> 200000
A7: ="ORD-2026-"&TEXT(ROW()-1,"0000") -> ORD-2026-0006 | B7: 45671 | C7: =TEXT(tblSales[[#This Row],[Date]],"mmmm") -> January | D7: Michael | E7: =_xlfn.XLOOKUP(tblSales[[#This Row],[Saleperson]],Lookup_Tables!$B$5:$B$16,Lookup_Tables!$C$5:$C$16) -> West | F7: Green Valley School | G7: =_xlfn.XLOOKUP(tblSales[[#This Row],[Customer]],Lookup_Tables!$I$5:$I$34,Lookup_Tables!$J$5:$J$34) -> Government | H7: =_xlfn.XLOOKUP(tblSales[[#This Row],[Product]],Lookup_Tables!$F$5:$F$23,Lookup_Tables!$E$5:$E$23,"") -> Office Supplies | I7: Scissors | J7: 2 | K7: =_xlfn.XLOOKUP(tblSales[[#This Row],[Product]],Lookup_Tables!$F$5:$F$23,Lookup_Tables!$G$5:$G$23,"") -> 190 | L7: =_xlfn.XLOOKUP(tblSales[[#This Row],[Customer Type]],Lookup_Tables!$B$19:$B$21,Lookup_Tables!$C$19:$C$21,0) -> 0.15 | M7: Gcash | N7: ="Q"&ROUNDUP(MONTH(tblSales[[#This Row],[Date]])/3,0) -> Q1 | O7: =YEAR(tblSales[[#This Row],[Date]]) -> 2025 | P7: =tblSales[[#This Row],[Quantity]]*tblSales[[#This Row],[Unit Price]] -> 380 | Q7: =tblSales[[#This Row],[Gross Sales]]*tblSales[[#This Row],[Discount%]] -> 57 | R7: =tblSales[[#This Row],[Gross Sales]]-tblSales[[#This Row],[Discount Amount]] -> 323
A8: ="ORD-2026-"&TEXT(ROW()-1,"0000") -> ORD-2026-0007 | B8: 45671 | C8: =TEXT(tblSales[[#This Row],[Date]],"mmmm") -> January | D8: Sophia | E8: =_xlfn.XLOOKUP(tblSales[[#This Row],[Saleperson]],Lookup_Tables!$B$5:$B$16,Lookup_Tables!$C$5:$C$16) -> North | F8: North Star Trading | G8: =_xlfn.XLOOKUP(tblSales[[#This Row],[Customer]],Lookup_Tables!$I$5:$I$34,Lookup_Tables!$J$5:$J$34) -> Government | H8: =_xlfn.XLOOKUP(tblSales[[#This Row],[Product]],Lookup_Tables!$F$5:$F$23,Lookup_Tables!$E$5:$E$23,"") -> Furniture | I8: Office Chair | J8: 5 | K8: =_xlfn.XLOOKUP(tblSales[[#This Row],[Product]],Lookup_Tables!$F$5:$F$23,Lookup_Tables!$G$5:$G$23,"") -> 4200 | L8: =_xlfn.XLOOKUP(tblSales[[#This Row],[Customer Type]],Lookup_Tables!$B$19:$B$21,Lookup_Tables!$C$19:$C$21,0) -> 0.15 | M8: Credit Card | N8: ="Q"&ROUNDUP(MONTH(tblSales[[#This Row],[Date]])/3,0) -> Q1 | O8: =YEAR(tblSales[[#This Row],[Date]]) -> 2025 | P8: =tblSales[[#This Row],[Quantity]]*tblSales[[#This Row],[Unit Price]] -> 21000 | Q8: =tblSales[[#This Row],[Gross Sales]]*tblSales[[#This Row],[Discount%]] -> 3150 | R8: =tblSales[[#This Row],[Gross Sales]]-tblSales[[#This Row],[Discount Amount]] -> 17850
A9: ="ORD-2026-"&TEXT(ROW()-1,"0000") -> ORD-2026-0008 | B9: 45671 | C9: =TEXT(tblSales[[#This Row],[Date]],"mmmm") -> January | D9: John | E9: =_xlfn.XLOOKUP(tblSales[[#This Row],[Saleperson]],Lookup_Tables!$B$5:$B$16,Lookup_Tables!$C$5:$C$16) -> North | F9: Prestige Holdings | G9: =_xlfn.XLOOKUP(tblSales[[#This Row],[Customer]],Lookup_Tables!$I$5:$I$34,Lookup_Tables!$J$5:$J$34) -> Corporate | H9: =_xlfn.XLOOKUP(tblSales[[#This Row],[Product]],Lookup_Tables!$F$5:$F$23,Lookup_Tables!$E$5:$E$23,"") -> Office Supplies | I9: Scissors | J9: 8 | K9: =_xlfn.XLOOKUP(tblSales[[#This Row],[Product]],Lookup_Tables!$F$5:$F$23,Lookup_Tables!$G$5:$G$23,"") -> 190 | L9: =_xlfn.XLOOKUP(tblSales[[#This Row],[Customer Type]],Lookup_Tables!$B$19:$B$21,Lookup_Tables!$C$19:$C$21,0) -> 0.1 | M9: Cash | N9: ="Q"&ROUNDUP(MONTH(tblSales[[#This Row],[Date]])/3,0) -> Q1 | O9: =YEAR(tblSales[[#This Row],[Date]]) -> 2025 | P9: =tblSales[[#This Row],[Quantity]]*tblSales[[#This Row],[Unit Price]] -> 1520 | Q9: =tblSales[[#This Row],[Gross Sales]]*tblSales[[#This Row],[Discount%]] -> 152 | R9: =tblSales[[#This Row],[Gross Sales]]-tblSales[[#This Row],[Discount Amount]] -> 1368
A10: ="ORD-2026-"&TEXT(ROW()-1,"0000") -> ORD-2026-0009 | B10: 45672 | C10: =TEXT(tblSales[[#This Row],[Date]],"mmmm") -> January | D10: Daniel | E10: =_xlfn.XLOOKUP(tblSales[[#This Row],[Saleperson]],Lookup_Tables!$B$5:$B$16,Lookup_Tables!$C$5:$C$16) -> East | F10: Prime Office Supply | G10: =_xlfn.XLOOKUP(tblSales[[#This Row],[Customer]],Lookup_Tables!$I$5:$I$34,Lookup_Tables!$J$5:$J$34) -> Retail | H10: =_xlfn.XLOOKUP(tblSales[[#This Row],[Product]],Lookup_Tables!$F$5:$F$23,Lookup_Tables!$E$5:$E$23,"") -> Furniture | I10: Cabinet | J10: 1 | K10: =_xlfn.XLOOKUP(tblSales[[#This Row],[Product]],Lookup_Tables!$F$5:$F$23,Lookup_Tables!$G$5:$G$23,"") -> 5200 | L10: =_xlfn.XLOOKUP(tblSales[[#This Row],[Customer Type]],Lookup_Tables!$B$19:$B$21,Lookup_Tables!$C$19:$C$21,0) -> 0 | M10: Gcash | N10: ="Q"&ROUNDUP(MONTH(tblSales[[#This Row],[Date]])/3,0) -> Q1 | O10: =YEAR(tblSales[[#This Row],[Date]]) -> 2025 | P10: =tblSales[[#This Row],[Quantity]]*tblSales[[#This Row],[Unit Price]] -> 5200 | Q10: =tblSales[[#This Row],[Gross Sales]]*tblSales[[#This Row],[Discount%]] -> 0 | R10: =tblSales[[#This Row],[Gross Sales]]-tblSales[[#This Row],[Discount Amount]] -> 5200
A11: ="ORD-2026-"&TEXT(ROW()-1,"0000") -> ORD-2026-0010 | B11: 45672 | C11: =TEXT(tblSales[[#This Row],[Date]],"mmmm") -> January | D11: Grace | E11: =_xlfn.XLOOKUP(tblSales[[#This Row],[Saleperson]],Lookup_Tables!$B$5:$B$16,Lookup_Tables!$C$5:$C$16) -> South | F11: Metro Electronics | G11: =_xlfn.XLOOKUP(tblSales[[#This Row],[Customer]],Lookup_Tables!$I$5:$I$34,Lookup_Tables!$J$5:$J$34) -> Retail | H11: =_xlfn.XLOOKUP(tblSales[[#This Row],[Product]],Lookup_Tables!$F$5:$F$23,Lookup_Tables!$E$5:$E$23,"") -> Electronics | I11: Projector | J11: 7 | K11: =_xlfn.XLOOKUP(tblSales[[#This Row],[Product]],Lookup_Tables!$F$5:$F$23,Lookup_Tables!$G$5:$G$23,"") -> 9500 | L11: =_xlfn.XLOOKUP(tblSales[[#This Row],[Customer Type]],Lookup_Tables!$B$19:$B$21,Lookup_Tables!$C$19:$C$21,0) -> 0 | M11: Cash | N11: ="Q"&ROUNDUP(MONTH(tblSales[[#This Row],[Date]])/3,0) -> Q1 | O11: =YEAR(tblSales[[#This Row],[Date]]) -> 2025 | P11: =tblSales[[#This Row],[Quantity]]*tblSales[[#This Row],[Unit Price]] -> 66500 | Q11: =tblSales[[#This Row],[Gross Sales]]*tblSales[[#This Row],[Discount%]] -> 0 | R11: =tblSales[[#This Row],[Gross Sales]]-tblSales[[#This Row],[Discount Amount]] -> 66500
A12: ="ORD-2026-"&TEXT(ROW()-1,"0000") -> ORD-2026-0011 | B12: 45675 | C12: =TEXT(tblSales[[#This Row],[Date]],"mmmm") -> January | D12: Mark | E12: =_xlfn.XLOOKUP(tblSales[[#This Row],[Saleperson]],Lookup_Tables!$B$5:$B$16,Lookup_Tables!$C$5:$C$16) -> West | F12: Prime Office Supply | G12: =_xlfn.XLOOKUP(tblSales[[#This Row],[Customer]],Lookup_Tables!$I$5:$I$34,Lookup_Tables!$J$5:$J$34) -> Retail | H12: =_xlfn.XLOOKUP(tblSales[[#This Row],[Product]],Lookup_Tables!$F$5:$F$23,Lookup_Tables!$E$5:$E$23,"") -> Office Supplies | I12: Printer | J12: 8 | K12: =_xlfn.XLOOKUP(tblSales[[#This Row],[Product]],Lookup_Tables!$F$5:$F$23,Lookup_Tables!$G$5:$G$23,"") -> 5000 | L12: =_xlfn.XLOOKUP(tblSales[[#This Row],[Customer Type]],Lookup_Tables!$B$19:$B$21,Lookup_Tables!$C$19:$C$21,0) -> 0 | M12: Gcash | N12: ="Q"&ROUNDUP(MONTH(tblSales[[#This Row],[Date]])/3,0) -> Q1 | O12: =YEAR(tblSales[[#This Row],[Date]]) -> 2025 | P12: =tblSales[[#This Row],[Quantity]]*tblSales[[#This Row],[Unit Price]] -> 40000 | Q12: =tblSales[[#This Row],[Gross Sales]]*tblSales[[#This Row],[Discount%]] -> 0 | R12: =tblSales[[#This Row],[Gross Sales]]-tblSales[[#This Row],[Discount Amount]] -> 40000
A13: ="ORD-2026-"&TEXT(ROW()-1,"0000") -> ORD-2026-0012 | B13: 45678 | C13: =TEXT(tblSales[[#This Row],[Date]],"mmmm") -> January | D13: Sarah | E13: =_xlfn.XLOOKUP(tblSales[[#This Row],[Saleperson]],Lookup_Tables!$B$5:$B$16,Lookup_Tables!$C$5:$C$16) -> West | F13: Metro Electronics | G13: =_xlfn.XLOOKUP(tblSales[[#This Row],[Customer]],Lookup_Tables!$I$5:$I$34,Lookup_Tables!$J$5:$J$34) -> Retail | H13: =_xlfn.XLOOKUP(tblSales[[#This Row],[Product]],Lookup_Tables!$F$5:$F$23,Lookup_Tables!$E$5:$E$23,"") -> Electronics | I13: Laptop | J13: 4 | K13: =_xlfn.XLOOKUP(tblSales[[#This Row],[Product]],Lookup_Tables!$F$5:$F$23,Lookup_Tables!$G$5:$G$23,"") -> 20000 | L13: =_xlfn.XLOOKUP(tblSales[[#This Row],[Customer Type]],Lookup_Tables!$B$19:$B$21,Lookup_Tables!$C$19:$C$21,0) -> 0 | M13: Cash | N13: ="Q"&ROUNDUP(MONTH(tblSales[[#This Row],[Date]])/3,0) -> Q1 | O13: =YEAR(tblSales[[#This Row],[Date]]) -> 2025 | P13: =tblSales[[#This Row],[Quantity]]*tblSales[[#This Row],[Unit Price]] -> 80000 | Q13: =tblSales[[#This Row],[Gross Sales]]*tblSales[[#This Row],[Discount%]] -> 0 | R13: =tblSales[[#This Row],[Gross Sales]]-tblSales[[#This Row],[Discount Amount]] -> 80000
... A301: ="ORD-2026-"&TEXT(ROW()-1,"0000") -> ORD-2026-0300 | B301: 46096 | C301: =TEXT(tblSales[[#This Row],[Date]],"mmmm") -> March | D301: Anna | E301: =_xlfn.XLOOKUP(tblSales[[#This Row],[Saleperson]],Lookup_Tables!$B$5:$B$16,Lookup_Tables!$C$5:$C$16) -> South | F301: Sunrise Retail | G301: =_xlfn.XLOOKUP(tblSales[[#This Row],[Customer]],Lookup_Tables!$I$5:$I$34,Lookup_Tables!$J$5:$J$34) -> Retail | H301: =_xlfn.XLOOKUP(tblSales[[#This Row],[Product]],Lookup_Tables!$F$5:$F$23,Lookup_Tables!$E$5:$E$23,"") -> Furniture | I301: Office Chair | J301: 5 | K301: =_xlfn.XLOOKUP(tblSales[[#This Row],[Product]],Lookup_Tables!$F$5:$F$23,Lookup_Tables!$G$5:$G$23,"") -> 4200 | L301: =_xlfn.XLOOKUP(tblSales[[#This Row],[Customer Type]],Lookup_Tables!$B$19:$B$21,Lookup_Tables!$C$19:$C$21,0) -> 0 | M301: Bank Transfer | N301: ="Q"&ROUNDUP(MONTH(tblSales[[#This Row],[Date]])/3,0) -> Q1 | O301: =YEAR(tblSales[[#This Row],[Date]]) -> 2026 | P301: =tblSales[[#This Row],[Quantity]]*tblSales[[#This Row],[Unit Price]] -> 21000 | Q301: =tblSales[[#This Row],[Gross Sales]]*tblSales[[#This Row],[Discount%]] -> 0 | R301: =tblSales[[#This Row],[Gross Sales]]-tblSales[[#This Row],[Discount Amount]] -> 21000

Sheet Lookup_Tables
B2: MASTER LOOKUP TABLES | E2: PRODUCT MASTER | I2: CUSTOMER MASTER
B4: Salesperson | C4: Region | E4: Product Category | F4: Product | G4: Unit Price | I4: Customer | J4: Customer Type
B5: John | C5: North | E5: Electronics | F5: Laptop | G5: 20000 | I5: ABC Corporation | J5: Corporate
B6: Anna | C6: South | E6: Electronics | F6: Monitor | G6: 6000 | I6: XYZ Trading | J6: Retail
B7: Mark | C7: West | E7: Electronics | F7: Projector | G7: 9500 | I7: Sunrise Retail | J7: Retail
B8: Jane | C8: East | E8: Electronics | F8: Keyboard | G8: 850 | I8: Prime Office Supply | J8: Retail
B9: David | C9: South | E9: Electronics | F9: Mouse | G9: 720 | I9: Metro Electronics | J9: Retail
B10: Peter | C10: North | E10: Furniture | F10: Office Chair | G10: 4200 | I10: Green Valley School | J10: Government
B11: Sarah | C11: West | E11: Furniture | F11: Desk | G11: 6900 | I11: City Government | J11: Government
B12: Kevin | C12: South | E12: Furniture | F12: Cabinet | G12: 5200 | I12: Tech Solutions Inc. | J12: Retail
B13: Michael | C13: West | E13: Furniture | F13: Shelf | G13: 3100 | I13: Golden Hardware | J13: Retail
B14: Sophia | C14: North | E14: Furniture | F14: Table | G14: 7500 | I14: North Star Trading | J14: Government
B15: Daniel | C15: East | E15: Office Supplies | F15: Printer | G15: 5000 | I15: Bright Future Academy | J15: Retail
B16: Grace | C16: South | E16: Office Supplies | F16: Notebook | G16: 120 | I16: Apex Manufacturing | J16: Retail
E17: Office Supplies | F17: Bond Paper | G17: 180 | I17: Central Pharmacy | J17: Retail
B18: Customer Type | C18: Discount | E18: Office Supplies | F18: Marker | G18: 90 | I18: Mega Builders | J18: Corporate
B19: Retail | C19: 0 | E19: Office Supplies | F19: Ballpen | G19: 60 | I19: Pacific Foods | J19: Retail
B20: Corporate | C20: 0.1 | E20: Office Supplies | F20: Envelope | G20: 32 | I20: Global Logistics | J20: Retail
B21: Government | C21: 0.15 | E21: Office Supplies | F21: Stapler | G21: 210 | I21: Silverline Stores | J21: Retail
E22: Office Supplies | F22: Folder | G22: 75 | I22: Horizon Enterprises | J22: Retail
C23: Payment Method | E23: Office Supplies | F23: Scissors | G23: 190 | I23: Elite Medical Center | J23: Retail
C24: Cash | I24: United Cooperative | J24: Corporate
C25: Credit Card | I25: Crystal Mart | J25: Retail
C26: Bank Transfer | I26: Summit Engineering | J26: Corporate
C27: Gcash | I27: Orion Industries | J27: Retail
I28: Blue Ocean Trading | J28: Retail
I29: First Choice Supplies | J29: Retail
I30: Alpha Distribution | J30: Corporate
I31: Nova Systems | J31: Corporate
I32: Evergreen Supermarket | J32: Retail
I33: Prestige Holdings | J33: Corporate
I34: Pioneer Construction | J34: Corporate

Sheet Analysis
B2: SALES BY MONTH | E2: SALESPERSON PERFORMANCE | J2: PRODUCT CATEGORY PERFORMANCE | Q2: KEY PERFORMANCE INDICATORS
B4: Month | C4: Sum of Net Sales | E4: Salesperson | F4: Sum of Net Sales | G4: Orders Count | H4: Avg. Order Value | J4: Category | K4: Sum of Net Sales | L4: QUANTITY SOLD | M4: % of TOTAL SALES | Q4: TOTAL NET SALES | R4: AVG. ORDER VALUE | S4: QUANTITY SOLD | T4: TOTAL ORDERS
B5: 2025 | C5: 5209174.4 | E5: Grace | F5: 967077.3 | G5: 51 | H5: 18962.3 | J5: Electronics | K5: 3581369 | L5: 79 | M5: 0.53050489
B6: January | C6: 697878 | E6: Kevin | F6: 830856 | G6: 21 | H6: 39564.571 | J6: Furniture | K6: 2726120 | L6: 85 | M6: 0.40381764 | Q6: Sum of Net Sales | R6: Average of Net Sales | S6: Sum of Quantity | T6: Count of Order ID
B7: February | C7: 319685 | E7: Sophia | F7: 788264.1 | G7: 25 | H7: 31530.564 | J7: Office Supplies | K7: 443380 | L7: 136 | M7: 0.065677471 | Q7: 6750869 | R7: 22502.897 | S7: 1720 | T7: 300
B8: March | C8: 127118.5 | E8: David | F8: 656345 | G8: 22 | H8: 29833.864 | J8: Grand Total | K8: 6750869 | L8: 300 | M8: 1
B9: April | C9: 254792 | E9: Michael | F9: 620988 | G9: 22 | H9: 28226.727
B10: May | C10: 255731 | E10: Anna | F10: 538828 | G10: 21 | H10: 25658.476
B11: June | C11: 414663 | E11: Peter | F11: 412299 | G11: 22 | H11: 18740.864 | J11: CUSTOMER TYPE PERFORMANCE 1
B12: July | C12: 524701.1 | E12: Daniel | F12: 407604.5 | G12: 27 | H12: 15096.463
B13: August | C13: 330526 | E13: Sarah | F13: 400739 | G13: 23 | H13: 17423.435 | K13: CUSTOMER TYPE | L13: Sum of Net Sales
B14: September | C14: 232291 | E14: Mark | F14: 390134.5 | G14: 24 | H14: 16255.604 | K14: Retail | L14: 4881738
B15: October | C15: 300802.5 | E15: Jane | F15: 370069.5 | G15: 21 | H15: 17622.357 | K15: Government | L15: 1108726.4
B16: November | C16: 1142820 | E16: John | F16: 367664.1 | G16: 21 | H16: 17507.814 | K16: Corporate | L16: 760404.6
B17: December | C17: 608166.3 | E17: Grand Total | F17: 6750869 | G17: 300 | H17: 22502.897 | K17: Grand Total | L17: 6750869
B18: 2026 | C18: 1541694.6
B19: January | C19: 872563
B20: February | C20: 355319.2 | E20: PRODUCT PERFORMANCE | J20: CUSTOMER TYPE PERFORMANCE 2
B21: March | C21: 313812.4
B22: Grand Total | C22: 6750869 | E22: PRODUCT | F22: SUM OF NET SALES | G22: QUANTITY SOLD | H22: % Of Total Sales | J22: CUSTOMER TYPE | K22: Sum of Net Sales | L22: QUANTITY SOLD | M22: % of TOTAL SALES
E23: Laptop | F23: 2277000 | G23: 19 | H23: 0.44194327 | J23: Retail | K23: 4881738 | L23: 207 | M23: 0.72312735
E24: Table | F24: 892125 | G24: 19 | H24: 0.17315267 | J24: Government | K24: 1108726.4 | L24: 65 | M24: 0.16423462
B25: SALES BY REGION | E25: Desk | F25: 809370 | G25: 19 | H25: 0.15709074 | J25: Corporate | K25: 760404.6 | L25: 28 | M25: 0.11263803
E26: Monitor | F26: 703500 | G26: 20 | H26: 0.13654242 | J26: Grand Total | K26: 6750869 | L26: 300 | M26: 1
B27: Region | C27: Sum of Net Sales | E27: Projector | F27: 470250 | G27: 9 | H27: 0.091270893
B28: South | C28: 2993106.3 | E28: Grand Total | F28: 5152245 | G28: 86 | H28: 1
B29: North | C29: 1568227.2 | J29: PAYMENT METHOD ANALYSIS
B30: West | C30: 1411861.5 | E30: Note: This Pivot Table contains all the list of products, but is filtered to only
B31: East | C31: 777674 | E31: show the Top 5 products with the highest sales on the Dashboard. To see all | J31: PRODUCT CATEGORY | K31: Sum of Net Sales | L31: ORDERS COUNT
B32: Grand Total | C32: 6750869 | E32: list, clear the filter but make sure to change the value filter back to Top 5 to | J32: Credit Card | K32: 1990251.5 | L32: 75
E33: not affect how the Pivot Chart is displayed on the dashboard. | J33: Bank Transfer | K33: 1902831.6 | L33: 72
J34: Gcash | K34: 1441242.4 | L34: 76
J35: Cash | K35: 1416543.5 | L35: 77
J36: Grand Total | K36: 6750869 | L36: 300
B86: PRODUCT CATEGORY PERFORMANCE
B88: Category | C88: Sum of Net Sales | F88: PRODUCT PERFORMANCE
B89: Electronics | C89: 3581369
B90: Furniture | C90: 2726120 | F90: PRODUCT | G90: SUM OF NET SALES
B91: Office Supplies | C91: 443380 | F91: Laptop | G91: 2277000
B92: Grand Total | C92: 6750869 | F92: Table | G92: 892125
...

Sheet Dashboard
G2: FY 2025 - Q1 2026 SALES PERFORMANCE DASHBOARD

Sheet README
B2: SALES PERFORMANCE DASHBOARD
B4: Project Overview
B6: I developed an interactive Sales Performance Dashboard using Microsoft Excel to transform raw sales transaction data into an interactive reporting and analysis tool.
B8: The workbook analyzes 300 sales transactions covering January 2025 to March 2026. It provides management-level KPIs and allows users to dynamically filter results by region, product category, customer type, salesperson, and date.
B10: PivotTables and PivotCharts were used as the analytical foundation, while slicers and a Timeline were implemented to provide an interactive user experience.
B12: Dataset
B14: Item | C14: Description
B15: Dataset | C15: Sales Transaction Data
B16: Number of Orders | C16: 300
B17: Period Covered | C17: January 2025 – March 2026
B18: Currency | C18: Philippine Peso (₱)
B19: Tool | C19: Microsoft Excel
B21: Key Dashboard Features
B23: 📊 KPI Monitoring | F23: 🛒 Product Analysis | L23: 🎛️ Interactive Filtering
B25: The dashboard displays: | F25: The dashboard identifies the Top 5 products by Net Sales. | L25: The dashboard includes:
B27: Total Net Sales: ₱6,750,869.00 | F27: 👥 Customer Analysis | L27: Region slicer
B29: Total Orders: 300 | F29: Sales can be evaluated by: | L29: Product Category slicer
B31: Quantity Sold: 1,720 | F31: Retail | L31: Customer Type slicer
B33: Average Order Value: ₱22,502.90 | F33: Government | L33: Salesperson slicer
B35: 📈 Sales Trend | F35: Corporate | L35: Year Timeline
B37: A monthly line chart allows users to identify changes in sales performance over time. | F37: 👨‍💼 Salesperson Analysis | L37: Quarter Timeline
B39: 🌎 Regional Analysis | F39: Users can compare salespeople based on: | L39: Month Timeline
B41: Sales are compared across: | F41: Net Sales | L41: Day Timeline
B43: South | F43: Order Count | L43: The KPI cards and charts respond dynamically to these filters.
B45: North | F45: Average Order Value
B47: West
B49: East
B262: Dashboard Features | D262: Key Metrics
B264: Interactive KPI cards | D264: Total Net Sales
B265: Monthly sales trend analysis | D265: Total Orders
B266: Regional sales analysis | D266: Total Quantity Sold
B267: Product category analysis | D267: Average Order Value
B268: Customer type analysis | D268: Discount Amount
B269: Top 5 product ranking
B270: Slicers for interactive filtering
B271: Date Timeline
B272: PivotTables and PivotCharts
B273: Automated KPI calculations
B275: Excel Skills Demonstrated
B277: Excel Tables
...

Sheet Report
B2: Key Business Insights
B6: 🥇 Product Category | O6: 👥 Customer Type
B8: Electronics generated the highest sales: | O8: Retail customers generated:
B10: ₱3,581,369.00 — 53.05% of total sales | O10: ₱4,881,738 — 72.31% of total sales
B12: Furniture followed with ₱2,726,120.00 (40.38%), while Office Supplies contributed ₱443,380.00 (6.57%). | O12: Government contributed 16.42%, while Corporate contributed 11.26%.
B14: Insight: Sales are heavily concentrated in Electronics and Furniture, which together account for approximately 93% of total sales. | O14: Insight: Retail is the company's dominant customer segment, suggesting that changes in retail demand could have a significant effect on overall revenue.
B18: 🏆 Top Product | O18: 🌎 Regional Performance
B20: Laptop was the strongest individual product: | O20: South was the strongest region:
B22: ₱2,277,000 — 44.19% of the Top 5 products' sales | O22: 2993106.3
B24: The other leading products were: | O24: It was followed by:
B26: 1. Laptop — ₱2,277,000 | O26: North — ₱1,568,227.20
B28: 2. Table — ₱892,125 | O28: West — ₱1,411,861.50
B30: 3. Desk — ₱809,370 | O30: East — ₱777,674.00
B32: 4. Monitor — ₱703,500 | O32: Insight: The South region generated substantially more sales than the other regions, while East represents an opportunity for further investigation and improvement.
B34: 5. Projector — ₱470,250
B36: Together, these five products generated ₱5,152,245, representing approximately 76.3% of total sales. | O36: 👨‍💼 Salesperson Performance
B38: Insight: Sales are highly concentrated among a small group of products, with Laptop sales particularly dominant. | O38: Grace had the highest Net Sales:
O40: ₱867,077.30 across 51 orders
O42: However, Kevin had the highest Average Order Value:
O44: 39564.57
O46: This is an excellent example of why looking at only total sales isn't enough.
O48: Insight: Grace leads in overall sales volume, while Kevin generates significantly higher value per order.
B52: Business Recommendations
B56: 1. Strengthen the Electronics category
B58: Electronics contributes more than half of total sales. The company could prioritize inventory, promotions, and cross-selling around high-performing electronics products.
B60: 2. Investigate the East region
B62: East generated considerably less revenue than the other regions. Management could investigate customer demand, salesperson performance, product availability, and marketing coverage in this region.
B64: 3. Protect the Retail customer base
B66: Since Retail contributes more than 70% of sales, maintaining customer retention and satisfaction in this segment should be a priority.
B68: 4. Analyze high-AOV sales strategies
B70: Kevin's high Average Order Value could provide useful information about successful selling techniques, product combinations, or customer segments that could potentially be replicated by other salespeople.
B72: 5. Monitor dependence on top products
B74: Because the Top 5 products account for roughly three-quarters of sales, the business should monitor inventory availability and avoid excessive dependence on a small number of products.
